<?xml version="1.0" encoding="utf-8"?>
<!-- This URDF was automatically created by SolidWorks to URDF Exporter! Originally created by Stephen Brawner (brawner@gmail.com) 
     Commit Version: 1.5.1-0-g916b5db  Build Version: 1.5.7152.31018
     For more information, please see http://wiki.ros.org/sw_urdf_exporter -->
<robot  name="GazeboV0" xmlns:xacro="http://www.ros.org/wiki/xacro">
  <xacro:include filename="$(find GazeboV0)/urdf/GazeboV0_gazebo_plugins.xacro"/>
  <link
    name="Chassis">
    <inertial>
      <origin
        xyz="0.0269095443731569 0.0453323740979076 0.00338251947577584"
        rpy="0 0 0" />
      <mass
        value="4.71173330321545" />
      <inertia
        ixx="0.131230257498409"
        ixy="-0.00965992784236992"
        ixz="-5.99613989356189E-08"
        iyy="0.195410162986863"
        iyz="6.45264756717054E-06"
        izz="0.183471725736634" />
    </inertial>
    <visual>
      <origin
        xyz="0 0 0"
        rpy="0 0 0" />
      <geometry>
        <mesh
          filename="package://GazeboV0/meshes/Chassis.STL" />
      </geometry>
      <material
        name="">
        <color
          rgba="0.898039215686275 0.917647058823529 0.929411764705882 1" />
      </material>
    </visual>
    <collision>
      <origin
        xyz="0 0 0"
        rpy="0 0 0" />
      <geometry>
        <mesh
          filename="package://GazeboV0/meshes/Chassis.STL" />
      </geometry>
    </collision>
  </link>
  <link
    name="RightWheel">
    <inertial>
      <origin
        xyz="-4.16333634234434E-17 0 0.00510000000000468"
        rpy="0 0 0" />
      <mass
        value="0.338614058747035" />
      <inertia
        ixx="0.000347581051317554"
        ixy="-1.01643953670217E-20"
        ixz="-2.39239615850713E-18"
        iyy="0.000347581051317554"
        iyz="4.29776253994726E-19"
        izz="0.000689518301963574" />
    </inertial>
    <visual>
      <origin
        xyz="0 0 0"
        rpy="0 0 0" />
      <geometry>
        <mesh
          filename="package://GazeboV0/meshes/RightWheel.STL" />
      </geometry>
      <material
        name="">
        <color
          rgba="0.898039215686275 0.917647058823529 0.929411764705882 1" />
      </material>
    </visual>
    <collision>
      <origin
        xyz="0 0 0"
        rpy="0 0 0" />
      <geometry>
        <mesh
          filename="package://GazeboV0/meshes/RightWheel.STL" />
      </geometry>
    </collision>
  </link>
  <joint
    name="RightRevolute"
    type="continuous">
    <origin
      xyz="0.040115 0.18594 -0.13626"
      rpy="-1.5708 0.15664 0" />
    <parent
      link="Chassis" />
    <child
      link="RightWheel" />
    <axis
      xyz="0 0 1" />
    <dynamics
      damping="0.01"
      friction="0.01" />
  </joint>
  <link
    name="LeftWheel">
    <inertial>
      <origin
        xyz="9.75608482889356E-15 -3.19189119579733E-16 -0.384296129215001"
        rpy="0 0 0" />
      <mass
        value="0.338614058747035" />
      <inertia
        ixx="0.000347581051317554"
        ixy="3.65109595413485E-32"
        ixz="-8.76963966855234E-18"
        iyy="0.000347581051317554"
        iyz="3.26098816688528E-19"
        izz="0.000689518301963574" />
    </inertial>
    <visual>
      <origin
        xyz="0 0 0"
        rpy="0 0 0" />
      <geometry>
        <mesh
          filename="package://GazeboV0/meshes/LeftWheel.STL" />
      </geometry>
      <material
        name="">
        <color
          rgba="0.898039215686275 0.917647058823529 0.929411764705882 1" />
      </material>
    </visual>
    <collision>
      <origin
        xyz="0 0 0"
        rpy="0 0 0" />
      <geometry>
        <mesh
          filename="package://GazeboV0/meshes/LeftWheel.STL" />
      </geometry>
    </collision>
  </link>
  <joint
    name="LeftRevolute"
    type="continuous">
    <origin
      xyz="0.040115 0.18594 -0.13626"
      rpy="-1.5708 -0.8089 0" />
    <parent
      link="Chassis" />
    <child
      link="LeftWheel" />
    <axis
      xyz="0 0 1" />
    <dynamics
      damping="0.01"
      friction="0.01" />
  </joint>
  <link
    name="FrontCastor">
    <inertial>
      <origin
        xyz="0.0030314489318095 0.0345627416364458 -2.33146835171283E-15"
        rpy="0 0 0" />
      <mass
        value="0.0671525104446695" />
      <inertia
        ixx="4.49259698602968E-05"
        ixy="-6.70501812216222E-06"
        ixz="6.59626907674286E-20"
        iyy="9.61913985679315E-06"
        iyz="3.5488033511995E-19"
        izz="4.97992078191438E-05" />
    </inertial>
    <visual>
      <origin
        xyz="0 0 0"
        rpy="0 0 0" />
      <geometry>
        <mesh
          filename="package://GazeboV0/meshes/FrontCastor.STL" />
      </geometry>
      <material
        name="">
        <color
          rgba="0.898039215686275 0.917647058823529 0.929411764705882 1" />
      </material>
    </visual>
    <collision>
      <origin
        xyz="0 0 0"
        rpy="0 0 0" />
      <geometry>
        <mesh
          filename="package://GazeboV0/meshes/FrontCastor.STL" />
      </geometry>
    </collision>
  </link>
  <joint
    name="FrontCastorRevolute"
    type="continuous">
    <origin
      xyz="-0.17901 -0.0033514 -0.11126"
      rpy="-1.5708 0 1.5956" />
    <parent
      link="Chassis" />
    <child
      link="FrontCastor" />
    <axis
      xyz="0 1 0" />
    <dynamics
      damping="0.01"
      friction="0.01" />
  </joint>
  <link
    name="FrontCastorWheel">
    <inertial>
      <origin
        xyz="0 -1.38777878078145E-17 -2.692290834716E-15"
        rpy="0 0 0" />
      <mass
        value="0.0317645176567402" />
      <inertia
        ixx="3.91504603938205E-06"
        ixy="7.41153828847513E-22"
        ixz="2.11096492323533E-21"
        iyy="3.91504603938204E-06"
        iyz="-3.64621214013375E-21"
        izz="7.40108172021949E-06" />
    </inertial>
    <visual>
      <origin
        xyz="0 0 0"
        rpy="0 0 0" />
      <geometry>
        <mesh
          filename="package://GazeboV0/meshes/FrontCastorWheel.STL" />
      </geometry>
      <material
        name="">
        <color
          rgba="0.898039215686275 0.917647058823529 0.929411764705882 1" />
      </material>
    </visual>
    <collision>
      <origin
        xyz="0 0 0"
        rpy="0 0 0" />
      <geometry>
        <mesh
          filename="package://GazeboV0/meshes/FrontCastorWheel.STL" />
      </geometry>
    </collision>
  </link>
  <joint
    name="FrontCastorWheelRevolute"
    type="continuous">
    <origin
      xyz="0.032 0.0675 0"
      rpy="0 0 1.984" />
    <parent
      link="FrontCastor" />
    <child
      link="FrontCastorWheel" />
    <axis
      xyz="0 0 1" />
    <dynamics
      damping="0.01"
      friction="0.01" />
  </joint>
  <link
    name="RearCastor">
    <inertial>
      <origin
        xyz="0.00303144893180851 0.0345627416364456 -1.22124532708767E-14"
        rpy="0 0 0" />
      <mass
        value="0.0671525104446697" />
      <inertia
        ixx="4.49259698602973E-05"
        ixy="-6.70501812216102E-06"
        ixz="3.2695471764016E-19"
        iyy="9.61913985679271E-06"
        iyz="1.94821687675364E-18"
        izz="4.97992078191438E-05" />
    </inertial>
    <visual>
      <origin
        xyz="0 0 0"
        rpy="0 0 0" />
      <geometry>
        <mesh
          filename="package://GazeboV0/meshes/RearCastor.STL" />
      </geometry>
      <material
        name="">
        <color
          rgba="0.898039215686275 0.917647058823529 0.929411764705882 1" />
      </material>
    </visual>
    <collision>
      <origin
        xyz="0 0 0"
        rpy="0 0 0" />
      <geometry>
        <mesh
          filename="package://GazeboV0/meshes/RearCastor.STL" />
      </geometry>
    </collision>
  </link>
  <joint
    name="RearCastorRevolute"
    type="continuous">
    <origin
      xyz="0.25924 -0.0033514 -0.11126"
      rpy="-1.5708 0 2.3562" />
    <parent
      link="Chassis" />
    <child
      link="RearCastor" />
    <axis
      xyz="0 1 0" />
    <dynamics
      damping="0.01"
      friction="0.01" />
  </joint>
  <link
    name="RearCastorWheel">
    <inertial>
      <origin
        xyz="0 2.77555756156289E-17 -1.01862962509358E-14"
        rpy="0 0 0" />
      <mass
        value="0.0317645176567403" />
      <inertia
        ixx="3.91504603938205E-06"
        ixy="-5.82335151237331E-22"
        ixz="-1.79994501291539E-21"
        iyy="3.91504603938205E-06"
        iyz="1.05879118406788E-22"
        izz="7.4010817202195E-06" />
    </inertial>
    <visual>
      <origin
        xyz="0 0 0"
        rpy="0 0 0" />
      <geometry>
        <mesh
          filename="package://GazeboV0/meshes/RearCastorWheel.STL" />
      </geometry>
      <material
        name="">
        <color
          rgba="0.898039215686275 0.917647058823529 0.929411764705882 1" />
      </material>
    </visual>
    <collision>
      <origin
        xyz="0 0 0"
        rpy="0 0 0" />
      <geometry>
        <mesh
          filename="package://GazeboV0/meshes/RearCastorWheel.STL" />
      </geometry>
    </collision>
  </link>
  <joint
    name="RearCastorWheelRevolute"
    type="continuous">
    <origin
      xyz="0.032 0.0675 0"
      rpy="0 0 0.34434" />
    <parent
      link="RearCastor" />
    <child
      link="RearCastorWheel" />
    <axis
      xyz="0 0 1" />
    <dynamics
      damping="0.01"
      friction="0.01" />
  </joint>
  <link
    name="Battery">
    <inertial>
      <origin
        xyz="-2.77555756156289E-17 0.0925 2.82152773367628E-15"
        rpy="0 0 0" />
      <mass
        value="17.512433" />
      <inertia
        ixx="0.172679886227083"
        ixy="-7.17521943866141E-17"
        ixz="-9.46607853575198E-16"
        iyy="0.333465911708333"
        iyz="2.24903143829696E-15"
        izz="0.260679862052083" />
    </inertial>
    <visual>
      <origin
        xyz="0 0 0"
        rpy="0 0 0" />
      <geometry>
        <mesh
          filename="package://GazeboV0/meshes/Battery.STL" />
      </geometry>
      <material
        name="">
        <color
          rgba="0.792156862745098 0.819607843137255 0.933333333333333 1" />
      </material>
    </visual>
    <collision>
      <origin
        xyz="0 0 0"
        rpy="0 0 0" />
      <geometry>
        <mesh
          filename="package://GazeboV0/meshes/Battery.STL" />
      </geometry>
    </collision>
  </link>
  <joint
    name="Fixed_Chassis_Battery"
    type="fixed">
    <origin
      xyz="0.040115 -0.0036514 0.097745"
      rpy="-1.5708 0 3.1416" />
    <parent
      link="Chassis" />
    <child
      link="Battery" />
    <axis
      xyz="0 0 0" />
  </joint>
  <link
    name="LiDAR">
    <inertial>
      <origin
        xyz="-2.77555756156289E-17 0.02 5.63785129692462E-18"
        rpy="0 0 0" />
      <mass
        value="0.064" />
      <inertia
        ixx="1.70666666666667E-05"
        ixy="2.58629900392802E-22"
        ixz="8.21376807141E-22"
        iyy="1.70666666666667E-05"
        iyz="1.20423640868724E-22"
        izz="1.70666666666667E-05" />
    </inertial>
    <visual>
      <origin
        xyz="0 0 0"
        rpy="0 0 0" />
      <geometry>
        <mesh
          filename="package://GazeboV0/meshes/LiDAR.STL" />
      </geometry>
      <material
        name="">
        <color
          rgba="0.792156862745098 0.819607843137255 0.933333333333333 1" />
      </material>
    </visual>
    <collision>
      <origin
        xyz="0 0 0"
        rpy="0 0 0" />
      <geometry>
        <mesh
          filename="package://GazeboV0/meshes/LiDAR.STL" />
      </geometry>
    </collision>
  </link>
  <joint
    name="Fixed_Battery_LiDAR"
    type="fixed">
    <origin
      xyz="-0.14989 -0.0033514 0.10474"
      rpy="0 0 3.1416" />
    <parent
      link="Chassis" />
    <child
      link="LiDAR" />
    <axis
      xyz="0 0 0" />
  </joint>
  <link
    name="WoodRod">
    <inertial>
      <origin
        xyz="-2.26988566831565E-15 -5.15756125557543E-06 0.650041260490045"
        rpy="0 0 0" />
      <mass
        value="0.701710470821045" />
      <inertia
        ixx="0.098880929063303"
        ixy="-5.19150998271822E-22"
        ixz="3.44989160057102E-16"
        iyy="0.0988809460746776"
        iyz="-3.62060800140933E-07"
        izz="0.000105225289802979" />
    </inertial>
    <visual>
      <origin
        xyz="0 0 0"
        rpy="0 0 0" />
      <geometry>
        <mesh
          filename="package://GazeboV0/meshes/WoodRod.STL" />
      </geometry>
      <material
        name="">
        <color
          rgba="1 1 1 1" />
      </material>
    </visual>
    <collision>
      <origin
        xyz="0 0 0"
        rpy="0 0 0" />
      <geometry>
        <mesh
          filename="package://GazeboV0/meshes/WoodRod.STL" />
      </geometry>
    </collision>
  </link>
  <joint
    name="Fixed_Chassis_WoodRod"
    type="fixed">
    <origin
      xyz="0.040115 -0.0033514 1.4407"
      rpy="3.1416 0 -1.5708" />
    <parent
      link="Chassis" />
    <child
      link="WoodRod" />
    <axis
      xyz="0 0 0" />
  </joint>
  <link
    name="TBS1">
    <inertial>
      <origin
        xyz="-2.08166817117217E-17 0 -0.00275"
        rpy="0 0 0" />
      <mass
        value="0.00173867551882195" />
      <inertia
        ixx="2.81242393072002E-08"
        ixy="-1.07733169308297E-25"
        ixz="6.43232433632577E-22"
        iyy="9.57958648484737E-08"
        iyz="4.9157531355283E-25"
        izz="1.1515428174828E-07" />
    </inertial>
    <visual>
      <origin
        xyz="0 0 0"
        rpy="0 0 0" />
      <geometry>
        <mesh
          filename="package://GazeboV0/meshes/TBS1.STL" />
      </geometry>
      <material
        name="">
        <color
          rgba="0.792156862745098 0.819607843137255 0.933333333333333 1" />
      </material>
    </visual>
    <collision>
      <origin
        xyz="0 0 0"
        rpy="0 0 0" />
      <geometry>
        <mesh
          filename="package://GazeboV0/meshes/TBS1.STL" />
      </geometry>
    </collision>
  </link>
  <joint
    name="Fixed_WoodRod_TBS1"
    type="fixed">
    <origin
      xyz="0 0.0205 1.05"
      rpy="-1.5708 0 0" />
    <parent
      link="WoodRod" />
    <child
      link="TBS1" />
    <axis
      xyz="0 0 0" />
  </joint>
  <link
    name="TBS2">
    <inertial>
      <origin
        xyz="-2.99239799605999E-17 0 -0.00275"
        rpy="0 0 0" />
      <mass
        value="0.00173867551882196" />
      <inertia
        ixx="2.81242393072003E-08"
        ixy="-7.56516223604374E-23"
        ixz="6.43735947518725E-22"
        iyy="9.57958648484739E-08"
        iyz="-2.36343625492949E-25"
        izz="1.1515428174828E-07" />
    </inertial>
    <visual>
      <origin
        xyz="0 0 0"
        rpy="0 0 0" />
      <geometry>
        <mesh
          filename="package://GazeboV0/meshes/TBS2.STL" />
      </geometry>
      <material
        name="">
        <color
          rgba="0.792156862745098 0.819607843137255 0.933333333333333 1" />
      </material>
    </visual>
    <collision>
      <origin
        xyz="0 0 0"
        rpy="0 0 0" />
      <geometry>
        <mesh
          filename="package://GazeboV0/meshes/TBS2.STL" />
      </geometry>
    </collision>
  </link>
  <joint
    name="Fixed_WoodRod_TBS2"
    type="fixed">
    <origin
      xyz="0 0.0205 0.85"
      rpy="-1.5707963267949 0 0" />
    <parent
      link="WoodRod" />
    <child
      link="TBS2" />
    <axis
      xyz="0 0 0" />
  </joint>
  <link
    name="TBS3">
    <inertial>
      <origin
        xyz="-2.12503625807159E-17 0 -0.00275"
        rpy="0 0 0" />
      <mass
        value="0.00173867551882195" />
      <inertia
        ixx="2.81242393072002E-08"
        ixy="-1.50916302612396E-22"
        ixz="6.44887958080419E-22"
        iyy="9.57958648484737E-08"
        iyz="-2.36343625492254E-25"
        izz="1.1515428174828E-07" />
    </inertial>
    <visual>
      <origin
        xyz="0 0 0"
        rpy="0 0 0" />
      <geometry>
        <mesh
          filename="package://GazeboV0/meshes/TBS3.STL" />
      </geometry>
      <material
        name="">
        <color
          rgba="0.792156862745098 0.819607843137255 0.933333333333333 1" />
      </material>
    </visual>
    <collision>
      <origin
        xyz="0 0 0"
        rpy="0 0 0" />
      <geometry>
        <mesh
          filename="package://GazeboV0/meshes/TBS3.STL" />
      </geometry>
    </collision>
  </link>
  <joint
    name="Fixed_WoodRod_TBS3"
    type="fixed">
    <origin
      xyz="0 0.0205 0.65"
      rpy="-1.5707963267949 0 0" />
    <parent
      link="WoodRod" />
    <child
      link="TBS3" />
    <axis
      xyz="0 0 0" />
  </joint>
  <link
    name="TBS4">
    <inertial>
      <origin
        xyz="2.73218947466347E-17 4.09782208166121E-11 -0.00275000000000001"
        rpy="0 0 0" />
      <mass
        value="0.00173867551882195" />
      <inertia
        ixx="2.81242393072002E-08"
        ixy="-1.57689833672588E-22"
        ixz="-6.4427241597485E-22"
        iyy="9.57958648484737E-08"
        iyz="-2.88462890935071E-16"
        izz="1.1515428174828E-07" />
    </inertial>
    <visual>
      <origin
        xyz="0 0 0"
        rpy="0 0 0" />
      <geometry>
        <mesh
          filename="package://GazeboV0/meshes/TBS4.STL" />
      </geometry>
      <material
        name="">
        <color
          rgba="0.792156862745098 0.819607843137255 0.933333333333333 1" />
      </material>
    </visual>
    <collision>
      <origin
        xyz="0 0 0"
        rpy="0 0 0" />
      <geometry>
        <mesh
          filename="package://GazeboV0/meshes/TBS4.STL" />
      </geometry>
    </collision>
  </link>
  <joint
    name="Fixed_WoodRod_TBS4"
    type="fixed">
    <origin
      xyz="0 0.015 0.45"
      rpy="1.57079631189374 0 0" />
    <parent
      link="WoodRod" />
    <child
      link="TBS4" />
    <axis
      xyz="0 0 0" />
  </joint>
  <link
    name="TBS5">
    <inertial>
      <origin
        xyz="3.03576608295941E-18 4.09781097943096E-11 -0.00275"
        rpy="0 0 0" />
      <mass
        value="0.00173867551882196" />
      <inertia
        ixx="2.81242393072001E-08"
        ixy="-1.73790056307107E-22"
        ixz="-6.47487423003288E-22"
        iyy="9.57958648484739E-08"
        iyz="-2.88462890345463E-16"
        izz="1.1515428174828E-07" />
    </inertial>
    <visual>
      <origin
        xyz="0 0 0"
        rpy="0 0 0" />
      <geometry>
        <mesh
          filename="package://GazeboV0/meshes/TBS5.STL" />
      </geometry>
      <material
        name="">
        <color
          rgba="0.792156862745098 0.819607843137255 0.933333333333333 1" />
      </material>
    </visual>
    <collision>
      <origin
        xyz="0 0 0"
        rpy="0 0 0" />
      <geometry>
        <mesh
          filename="package://GazeboV0/meshes/TBS5.STL" />
      </geometry>
    </collision>
  </link>
  <joint
    name="Fixed_WoodRod_TBS5"
    type="fixed">
    <origin
      xyz="0 0.015 0.25"
      rpy="1.57079631189374 0 0" />
    <parent
      link="WoodRod" />
    <child
      link="TBS5" />
    <axis
      xyz="0 0 0" />
  </joint>
  <link
    name="TBS6">
    <inertial>
      <origin
        xyz="-3.86902350435481E-11 3.69675751390464E-05 0.00274975151575344"
        rpy="0 0 0" />
      <mass
        value="0.00173867551882195" />
      <inertia
        ixx="2.81242393072E-08"
        ixy="-3.66121094548663E-18"
        ixz="-1.22450245460564E-15"
        iyy="9.5799363062521E-08"
        iyz="2.60206933872073E-10"
        izz="1.15150783534232E-07" />
    </inertial>
    <visual>
      <origin
        xyz="0 0 0"
        rpy="0 0 0" />
      <geometry>
        <mesh
          filename="package://GazeboV0/meshes/TBS6.STL" />
      </geometry>
      <material
        name="">
        <color
          rgba="0.792156862745098 0.819607843137255 0.933333333333333 1" />
      </material>
    </visual>
    <collision>
      <origin
        xyz="0 0 0"
        rpy="0 0 0" />
      <geometry>
        <mesh
          filename="package://GazeboV0/meshes/TBS6.STL" />
      </geometry>
    </collision>
  </link>
  <joint
    name="Fixed_WoodRod_TBS6"
    type="fixed">
    <origin
      xyz="0 0.015 0.0500000000000003"
      rpy="-1.55735316729788 0 0" />
    <parent
      link="WoodRod" />
    <child
      link="TBS6" />
    <axis
      xyz="0 0 0" />
  </joint>
  <link
    name="Camera">
    <inertial>
      <origin
        xyz="0 0.0025 0"
        rpy="0 0 0" />
      <mass
        value="0.000125" />
      <inertia
        ixx="5.20833333333335E-10"
        ixy="3.24240024973725E-25"
        ixz="2.35533258742828E-26"
        iyy="5.20833333333335E-10"
        iyz="-4.66256020423435E-25"
        izz="5.20833333333335E-10" />
    </inertial>
    <visual>
      <origin
        xyz="0 0 0"
        rpy="0 0 0" />
      <geometry>
        <mesh
          filename="package://GazeboV0/meshes/Camera.STL" />
      </geometry>
      <material
        name="">
        <color
          rgba="0.792156862745098 0.819607843137255 0.933333333333333 1" />
      </material>
    </visual>
    <collision>
      <origin
        xyz="0 0 0"
        rpy="0 0 0" />
      <geometry>
        <mesh
          filename="package://GazeboV0/meshes/Camera.STL" />
      </geometry>
    </collision>
  </link>
  <joint
    name="Fixed_Chassis_Camera"
    type="fixed">
    <origin
      xyz="-0.19689 -0.00085136 0.14724"
      rpy="-3.1416 0 0" />
    <parent
      link="Chassis" />
    <child
      link="Camera" />
    <axis
      xyz="0 0 0" />
  </joint>
</robot>

